Workbook

Sheet Products
A1: ProductID | B1: Product | C1: Price
A2: 101 | B2: Product A | C2: 120
A3: 102 | B3: Product B | C3: 150
A4: 103 | B4: Product C | C4: 200
A5: 104 | B5: Product D | C5: 90
A6: 105 | B6: Product E | C6: 220
A7: 106 | B7: Product F | C7: 130
A8: 5. Find Max Order Value
A9: =MAX(C2:C7) -> 220
A11: 6. Find Products that were NOT ordered
A12: =IF(COUNTIF(Orders!$B$2:$B$7, A2)=0, "Not Ordered", "Ordered") -> Ordered
A13: =IF(COUNTIF(Orders!$B$2:$B$7, A3)=0, "Not Ordered", "Ordered") -> Ordered
A14: =IF(COUNTIF(Orders!$B$2:$B$7, A4)=0, "Not Ordered", "Ordered") -> Ordered
A15: =IF(COUNTIF(Orders!$B$2:$B$7, A5)=0, "Not Ordered", "Ordered") -> Ordered
A16: =IF(COUNTIF(Orders!$B$2:$B$7, A6)=0, "Not Ordered", "Ordered") -> Ordered
A17: =IF(COUNTIF(Orders!$B$2:$B$7, A7)=0, "Not Ordered", "Ordered") -> Ordered
A19: IF(COUNTIF(Orders!$B$2:$B$7, A2)=0, "Not Ordered", "Ordered")
A21: 7. Find Product Name + Total Quantity Sold
A22: =SUMIF(Orders!$B$2:$B$7, A2, Orders!$C$2:$C$7) -> 2
A23: =SUMIF(Orders!$B$2:$B$7, A3, Orders!$C$2:$C$7) -> 5
A24: =SUMIF(Orders!$B$2:$B$7, A4, Orders!$C$2:$C$7) -> 1
A25: =SUMIF(Orders!$B$2:$B$7, A5, Orders!$C$2:$C$7) -> 6
A26: =SUMIF(Orders!$B$2:$B$7, A6, Orders!$C$2:$C$7) -> 3
A27: =SUMIF(Orders!$B$2:$B$7, A7, Orders!$C$2:$C$7) -> 4

Sheet Orders
A1: OrderID | B1: ProductID | C1: Quantity | D1: TotalPrice
A2: 1 | B2: 101 | C2: 2
A3: 2 | B3: 103 | C3: 1
A4: 3 | B4: 105 | C4: 3
A5: 4 | B5: 106 | C5: 4
A6: 5 | B6: 102 | C6: 5
A7: 6 | B7: 104 | C7: 6
A9: 2. Calculate Total Price
A10: =C2 * VLOOKUP(B2, Products!$A$2:$C$7, 3, FALSE) -> 240
A11: =C3 * VLOOKUP(B3, Products!$A$2:$C$7, 3, FALSE) -> 200
A12: =C4 * VLOOKUP(B4, Products!$A$2:$C$7, 3, FALSE) -> 660
A13: =C5 * VLOOKUP(B5, Products!$A$2:$C$7, 3, FALSE) -> 520
A14: =C6 * VLOOKUP(B6, Products!$A$2:$C$7, 3, FALSE) -> 750
A15: =C7 * VLOOKUP(B7, Products!$A$2:$C$7, 3, FALSE) -> 540
A17: C2 * VLOOKUP(B2, Products!$A$2:$C$7, 3, FALSE)
A19: 1. Find Product Names from ProductID
A20: =VLOOKUP(B2, Products!$A$2:$C$7, 2, FALSE) -> Product A
A21: =VLOOKUP(B3, Products!$A$2:$C$7, 2, FALSE) -> Product C
A22: =VLOOKUP(B4, Products!$A$2:$C$7, 2, FALSE) -> Product E
A23: =VLOOKUP(B5, Products!$A$2:$C$7, 2, FALSE) -> Product F
A24: =VLOOKUP(B6, Products!$A$2:$C$7, 2, FALSE) -> Product B
A25: =VLOOKUP(B7, Products!$A$2:$C$7, 2, FALSE) -> Product D
A27: VLOOKUP(B2, Products!$A$2:$C$7, 2, FALSE)
A29: 3. Check if any ProductIDs are missing
A30: =IF(ISNA(VLOOKUP(B2, Products!$A$2:$A$7, 1, FALSE)), "Missing", "Exists") -> Exists
A31: =IF(ISNA(VLOOKUP(B3, Products!$A$2:$A$7, 1, FALSE)), "Missing", "Exists") -> Exists
A32: =IF(ISNA(VLOOKUP(B4, Products!$A$2:$A$7, 1, FALSE)), "Missing", "Exists") -> Exists
A33: =IF(ISNA(VLOOKUP(B5, Products!$A$2:$A$7, 1, FALSE)), "Missing", "Exists") -> Exists
A34: =IF(ISNA(VLOOKUP(B6, Products!$A$2:$A$7, 1, FALSE)), "Missing", "Exists") -> Exists
A35: =IF(ISNA(VLOOKUP(B7, Products!$A$2:$A$7, 1, FALSE)), "Missing", "Exists") -> Exists
A37: IF(ISNA(VLOOKUP(B2, Products!$A$2:$A$7, 1, FALSE)), "Missing", "Exists")
A39: 4. Apply 10% Discount & Find Discounted Price
A40: =VLOOKUP(B2, Products!$A$2:$C$7, 3, FALSE) * 0.9 -> 108
A41: =VLOOKUP(B3, Products!$A$2:$C$7, 3, FALSE) * 0.9 -> 180
A42: =VLOOKUP(B4, Products!$A$2:$C$7, 3, FALSE) * 0.9 -> 198
A43: =VLOOKUP(B5, Products!$A$2:$C$7, 3, FALSE) * 0.9 -> 117
A44: =VLOOKUP(B6, Products!$A$2:$C$7, 3, FALSE) * 0.9 -> 135
A45: =VLOOKUP(B7, Products!$A$2:$C$7, 3, FALSE) * 0.9 -> 81
A47: VLOOKUP(B2, Products!$A$2:$C$7, 3, FALSE) * 0.9
A49: 7. Find Product Name + Total Quantity Sold
...
